Failure # 1 (occurred at 2025-06-12_23-27-14)
[36mray::ImplicitFunc.train()[39m (pid=21795, ip=172.17.0.2, actor_id=7afcf5c9bdd27ec7556ccda810000000, repr=bad_train_fn)
  File "/usr/local/lib/python3.10/dist-packages/ray/tune/trainable/trainable.py", line 331, in train
    raise skipped from exception_cause(skipped)
  File "/usr/local/lib/python3.10/dist-packages/ray/air/_internal/util.py", line 104, in run
    self._ret = self._target(*self._args, **self._kwargs)
  File "/usr/local/lib/python3.10/dist-packages/ray/tune/trainable/function_trainable.py", line 45, in <lambda>
    training_func=lambda: self._trainable_func(self.config),
  File "/usr/local/lib/python3.10/dist-packages/ray/tune/trainable/function_trainable.py", line 250, in _trainable_func
    output = fn()
  File "/workspaces/trading-rl-agent/tests/test_optimization.py", line 371, in bad_train_fn
    raise RuntimeError("fail")
RuntimeError: fail
