Failure # 1 (occurred at 2025-06-13_14-32-06)
[36mray::ImplicitFunc.train()[39m (pid=24456, ip=172.17.0.2, actor_id=fb913306457621aa0d80138601000000, repr=train_cnn_lstm_tune)
  File "/usr/local/lib/python3.10/dist-packages/ray/tune/trainable/trainable.py", line 331, in train
    raise skipped from exception_cause(skipped)
  File "/usr/local/lib/python3.10/dist-packages/ray/air/_internal/util.py", line 104, in run
    self._ret = self._target(*self._args, **self._kwargs)
  File "/usr/local/lib/python3.10/dist-packages/ray/tune/trainable/function_trainable.py", line 45, in <lambda>
    training_func=lambda: self._trainable_func(self.config),
  File "/usr/local/lib/python3.10/dist-packages/ray/tune/trainable/function_trainable.py", line 250, in _trainable_func
    output = fn()
  File "/tmp/ipykernel_19459/1682853855.py", line 10, in train_cnn_lstm_tune
TypeError: CNNLSTMConfig.__init__() got an unexpected keyword argument 'cnn_kernel_size'
